Workbook

Sheet Notes
A1: Ontario substance harms forecast: Excel version
A2: Source: Public Health Agency of Canada, Opioid- and stimulant-related harms in Canada, Health Infobase, SubstanceHarmsData.csv, downloaded 25 October 2026. Open Government Licence - Canada.
A3: Data: Ontario quarterly counts (overall numbers). Opioid deaths and both hospitalization series run from Q1 2016 to Q1 2026; stimulant deaths start in Q1 2018.
A4: Holdout: FORECAST.ETS is fit on quarters up to Q3 2024 and compared with the actual counts for Q4 2024 to Q1 2026. A seasonal naive forecast (the same quarter of the last training year) is the baseline.
A5: Forecast: FORECAST.ETS is fit on every quarter and projects Q2 2026 to Q2 2027 with 80% and 95% intervals from FORECAST.ETS.CONFINT. Seasonality is set to 4 (quarterly).
A6: Colours: blue numbers on the Data sheet are values typed in from the source file; black cells are formulas; green cells pull from another sheet.
A7: Excel's ETS is a different model from the Python ARIMA, so the numbers will not match the Python results exactly.

Sheet Data
A1: Quarter | B1: Quarter start | C1: Opioid deaths | D1: Stimulant deaths | E1: Opioid hospitalizations | F1: Stimulant hospitalizations
A2: 2016 Q1 | B2: =DATE(2016,1,1) -> 42370 | C2: 214 | E2: 374 | F2: 137
A3: 2016 Q2 | B3: =DATE(2016,4,1) -> 42461 | C3: 218 | E3: 485 | F3: 204
A4: 2016 Q3 | B4: =DATE(2016,7,1) -> 42552 | C4: 195 | E4: 442 | F4: 201
A5: 2016 Q4 | B5: =DATE(2016,10,1) -> 42644 | C5: 240 | E5: 497 | F5: 176
A6: 2017 Q1 | B6: =DATE(2017,1,1) -> 42736 | C6: 238 | E6: 472 | F6: 186
A7: 2017 Q2 | B7: =DATE(2017,4,1) -> 42826 | C7: 311 | E7: 523 | F7: 242
A8: 2017 Q3 | B8: =DATE(2017,7,1) -> 42917 | C8: 414 | E8: 562 | F8: 243
A9: 2017 Q4 | B9: =DATE(2017,10,1) -> 43009 | C9: 302 | E9: 506 | F9: 234
A10: 2018 Q1 | B10: =DATE(2018,1,1) -> 43101 | C10: 318 | D10: 180 | E10: 466 | F10: 250
A11: 2018 Q2 | B11: =DATE(2018,4,1) -> 43191 | C11: 336 | D11: 223 | E11: 562 | F11: 301
A12: 2018 Q3 | B12: =DATE(2018,7,1) -> 43282 | C12: 402 | D12: 254 | E12: 513 | F12: 298
A13: 2018 Q4 | B13: =DATE(2018,10,1) -> 43374 | C13: 457 | D13: 292 | E13: 525 | F13: 253
A14: 2019 Q1 | B14: =DATE(2019,1,1) -> 43466 | C14: 457 | D14: 293 | E14: 507 | F14: 237
A15: 2019 Q2 | B15: =DATE(2019,4,1) -> 43556 | C15: 481 | D15: 302 | E15: 571 | F15: 293
A16: 2019 Q3 | B16: =DATE(2019,7,1) -> 43647 | C16: 250 | D16: 174 | E16: 451 | F16: 220
A17: 2019 Q4 | B17: =DATE(2019,10,1) -> 43739 | C17: 377 | D17: 282 | E17: 436 | F17: 221
A18: 2020 Q1 | B18: =DATE(2020,1,1) -> 43831 | C18: 474 | D18: 314 | E18: 453 | F18: 241
A19: 2020 Q2 | B19: =DATE(2020,4,1) -> 43922 | C19: 631 | D19: 488 | E19: 513 | F19: 331
A20: 2020 Q3 | B20: =DATE(2020,7,1) -> 44013 | C20: 646 | D20: 461 | E20: 532 | F20: 259
A21: 2020 Q4 | B21: =DATE(2020,10,1) -> 44105 | C21: 733 | D21: 510 | E21: 520 | F21: 271
A22: 2021 Q1 | B22: =DATE(2021,1,1) -> 44197 | C22: 745 | D22: 541 | E22: 584 | F22: 225
A23: 2021 Q2 | B23: =DATE(2021,4,1) -> 44287 | C23: 737 | D23: 507 | E23: 606 | F23: 260
A24: 2021 Q3 | B24: =DATE(2021,7,1) -> 44378 | C24: 688 | D24: 553 | E24: 619 | F24: 261
A25: 2021 Q4 | B25: =DATE(2021,10,1) -> 44470 | C25: 710 | D25: 545 | E25: 610 | F25: 249
A26: 2022 Q1 | B26: =DATE(2022,1,1) -> 44562 | C26: 645 | D26: 493 | E26: 484 | F26: 216
A27: 2022 Q2 | B27: =DATE(2022,4,1) -> 44652 | C27: 594 | D27: 480 | E27: 492 | F27: 202
A28: 2022 Q3 | B28: =DATE(2022,7,1) -> 44743 | C28: 619 | D28: 483 | E28: 523 | F28: 232
A29: 2022 Q4 | B29: =DATE(2022,10,1) -> 44835 | C29: 673 | D29: 515 | E29: 511 | F29: 187
A30: 2023 Q1 | B30: =DATE(2023,1,1) -> 44927 | C30: 659 | D30: 577 | E30: 538 | F30: 226
A31: 2023 Q2 | B31: =DATE(2023,4,1) -> 45017 | C31: 691 | D31: 600 | E31: 579 | F31: 259
A32: 2023 Q3 | B32: =DATE(2023,7,1) -> 45108 | C32: 664 | D32: 569 | E32: 547 | F32: 276
A33: 2023 Q4 | B33: =DATE(2023,10,1) -> 45200 | C33: 631 | D33: 589 | E33: 536 | F33: 233
A34: 2024 Q1 | B34: =DATE(2024,1,1) -> 45292 | C34: 598 | D34: 523 | E34: 559 | F34: 229
A35: 2024 Q2 | B35: =DATE(2024,4,1) -> 45383 | C35: 652 | D35: 619 | E35: 554 | F35: 253
A36: 2024 Q3 | B36: =DATE(2024,7,1) -> 45474 | C36: 581 | D36: 569 | E36: 540 | F36: 251
A37: 2024 Q4 | B37: =DATE(2024,10,1) -> 45566 | C37: 436 | D37: 423 | E37: 415 | F37: 209
A38: 2025 Q1 | B38: =DATE(2025,1,1) -> 45658 | C38: 330 | D38: 348 | E38: 389 | F38: 174
A39: 2025 Q2 | B39: =DATE(2025,4,1) -> 45748 | C39: 327 | D39: 377 | E39: 409 | F39: 184
A40: 2025 Q3 | B40: =DATE(2025,7,1) -> 45839 | C40: 362 | D40: 383 | E40: 479 | F40: 262
...

Sheet Holdout
A1: Holdout test: fit to Q3 2024, test Q4 2024 to Q1 2026
A3: Opioid deaths
A4: Quarter | B4: Actual | C4: ETS forecast | D4: 95% low | E4: 95% high | F4: Seasonal naive | G4: ETS abs error | H4: ETS abs % error | I4: Naive abs error | J4: Naive abs % error
A5: 2024 Q4 | B5: =Data!C37 -> 436 | C5: =_xlfn.FORECAST.ETS(Data!B37,Data!$C$2:$C$36,Data!$B$2:$B$36,4) -> 626.44833 | D5: =C5-_xlfn.FORECAST.ETS.CONFINT(Data!B37,Data!$C$2:$C$36,Data!$B$2:$B$36,0.95,4) -> 513.5317 | E5: =C5+_xlfn.FORECAST.ETS.CONFINT(Data!B37,Data!$C$2:$C$36,Data!$B$2:$B$36,0.95,4) -> 741.42328 | F5: =Data!C33 -> 631 | G5: =ABS(C5-B5) -> 190.44833 | H5: =G5/B5 -> 0.4368081 | I5: =ABS(F5-B5) -> 195 | J5: =I5/B5 -> 0.44724771
A6: 2025 Q1 | B6: =Data!C38 -> 330 | C6: =_xlfn.FORECAST.ETS(Data!B38,Data!$C$2:$C$36,Data!$B$2:$B$36,4) -> 624.05113 | D6: =C6-_xlfn.FORECAST.ETS.CONFINT(Data!B38,Data!$C$2:$C$36,Data!$B$2:$B$36,0.95,4) -> 486.42166 | E6: =C6+_xlfn.FORECAST.ETS.CONFINT(Data!B38,Data!$C$2:$C$36,Data!$B$2:$B$36,0.95,4) -> 776.04598 | F6: =Data!C34 -> 598 | G6: =ABS(C6-B6) -> 294.05113 | H6: =G6/B6 -> 0.89106404 | I6: =ABS(F6-B6) -> 268 | J6: =I6/B6 -> 0.81212121
A7: 2025 Q2 | B7: =Data!C39 -> 327 | C7: =_xlfn.FORECAST.ETS(Data!B39,Data!$C$2:$C$36,Data!$B$2:$B$36,4) -> 703.15393 | D7: =C7-_xlfn.FORECAST.ETS.CONFINT(Data!B39,Data!$C$2:$C$36,Data!$B$2:$B$36,0.95,4) -> 545.38687 | E7: =C7+_xlfn.FORECAST.ETS.CONFINT(Data!B39,Data!$C$2:$C$36,Data!$B$2:$B$36,0.95,4) -> 863.65203 | F7: =Data!C35 -> 652 | G7: =ABS(C7-B7) -> 376.15393 | H7: =G7/B7 -> 1.1503178 | I7: =ABS(F7-B7) -> 325 | J7: =I7/B7 -> 0.99388379
A8: 2025 Q3 | B8: =Data!C40 -> 362 | C8: =_xlfn.FORECAST.ETS(Data!B40,Data!$C$2:$C$36,Data!$B$2:$B$36,4) -> 679.75674 | D8: =C8-_xlfn.FORECAST.ETS.CONFINT(Data!B40,Data!$C$2:$C$36,Data!$B$2:$B$36,0.95,4) -> 482.16712 | E8: =C8+_xlfn.FORECAST.ETS.CONFINT(Data!B40,Data!$C$2:$C$36,Data!$B$2:$B$36,0.95,4) -> 870.42928 | F8: =Data!C36 -> 581 | G8: =ABS(C8-B8) -> 317.75674 | H8: =G8/B8 -> 0.87778104 | I8: =ABS(F8-B8) -> 219 | J8: =I8/B8 -> 0.60497238
A9: 2025 Q4 | B9: =Data!C41 -> 398 | C9: =_xlfn.FORECAST.ETS(Data!B41,Data!$C$2:$C$36,Data!$B$2:$B$36,4) -> 724.35954 | D9: =C9-_xlfn.FORECAST.ETS.CONFINT(Data!B41,Data!$C$2:$C$36,Data!$B$2:$B$36,0.95,4) -> 515.20539 | E9: =C9+_xlfn.FORECAST.ETS.CONFINT(Data!B41,Data!$C$2:$C$36,Data!$B$2:$B$36,0.95,4) -> 928.14804 | F9: =Data!C33 -> 631 | G9: =ABS(C9-B9) -> 326.35954 | H9: =G9/B9 -> 0.81999884 | I9: =ABS(F9-B9) -> 233 | J9: =I9/B9 -> 0.58542714
A10: 2026 Q1 | B10: =Data!C42 -> 389 | C10: =_xlfn.FORECAST.ETS(Data!B42,Data!$C$2:$C$36,Data!$B$2:$B$36,4) -> 721.96234 | D10: =C10-_xlfn.FORECAST.ETS.CONFINT(Data!B42,Data!$C$2:$C$36,Data!$B$2:$B$36,0.95,4) -> 503.22956 | E10: =C10+_xlfn.FORECAST.ETS.CONFINT(Data!B42,Data!$C$2:$C$36,Data!$B$2:$B$36,0.95,4) -> 919.9458 | F10: =Data!C34 -> 598 | G10: =ABS(C10-B10) -> 332.96234 | H10: =G10/B10 -> 0.85594431 | I10: =ABS(F10-B10) -> 209 | J10: =I10/B10 -> 0.53727506
A11: MAE / MAPE | C11: Inside 95%: | D11: =SUMPRODUCT((B5:B10>=D5:D10)*(B5:B10<=E5:E10))&" of 6" -> 0 of 6 | G11: =AVERAGE(G5:G10) -> 306.28867 | H11: =AVERAGE(H5:H10) -> 0.83865236 | I11: =AVERAGE(I5:I10) -> 241.5 | J11: =AVERAGE(J5:J10) -> 0.66348788
A15: Stimulant deaths
A16: Quarter | B16: Actual | C16: ETS forecast | D16: 95% low | E16: 95% high | F16: Seasonal naive | G16: ETS abs error | H16: ETS abs % error | I16: Naive abs error | J16: Naive abs % error
A17: 2024 Q4 | B17: =Data!D37 -> 423 | C17: =_xlfn.FORECAST.ETS(Data!B37,Data!$D$10:$D$36,Data!$B$10:$B$36,4) -> 607.58126 | D17: =C17-_xlfn.FORECAST.ETS.CONFINT(Data!B37,Data!$D$10:$D$36,Data!$B$10:$B$36,0.95,4) -> 500.89029 | E17: =C17+_xlfn.FORECAST.ETS.CONFINT(Data!B37,Data!$D$10:$D$36,Data!$B$10:$B$36,0.95,4) -> 709.42546 | F17: =Data!D33 -> 589 | G17: =ABS(C17-B17) -> 184.58126 | H17: =G17/B17 -> 0.43636232 | I17: =ABS(F17-B17) -> 166 | J17: =I17/B17 -> 0.39243499
A18: 2025 Q1 | B18: =Data!D38 -> 348 | C18: =_xlfn.FORECAST.ETS(Data!B38,Data!$D$10:$D$36,Data!$B$10:$B$36,4) -> 609.4725 | D18: =C18-_xlfn.FORECAST.ETS.CONFINT(Data!B38,Data!$D$10:$D$36,Data!$B$10:$B$36,0.95,4) -> 497.49699 | E18: =C18+_xlfn.FORECAST.ETS.CONFINT(Data!B38,Data!$D$10:$D$36,Data!$B$10:$B$36,0.95,4) -> 724.60405 | F18: =Data!D34 -> 523 | G18: =ABS(C18-B18) -> 261.4725 | H18: =G18/B18 -> 0.75135776 | I18: =ABS(F18-B18) -> 175 | J18: =I18/B18 -> 0.50287356
A19: 2025 Q2 | B19: =Data!D39 -> 377 | C19: =_xlfn.FORECAST.ETS(Data!B39,Data!$D$10:$D$36,Data!$B$10:$B$36,4) -> 623.2264 | D19: =C19-_xlfn.FORECAST.ETS.CONFINT(Data!B39,Data!$D$10:$D$36,Data!$B$10:$B$36,0.95,4) -> 497.55887 | E19: =C19+_xlfn.FORECAST.ETS.CONFINT(Data!B39,Data!$D$10:$D$36,Data!$B$10:$B$36,0.95,4) -> 748.24278 | F19: =Data!D35 -> 619 | G19: =ABS(C19-B19) -> 246.2264 | H19: =G19/B19 -> 0.65312041 | I19: =ABS(F19-B19) -> 242 | J19: =I19/B19 -> 0.64190981
A20: 2025 Q3 | B20: =Data!D40 -> 383 | C20: =_xlfn.FORECAST.ETS(Data!B40,Data!$D$10:$D$36,Data!$B$10:$B$36,4) -> 597.28716 | D20: =C20-_xlfn.FORECAST.ETS.CONFINT(Data!B40,Data!$D$10:$D$36,Data!$B$10:$B$36,0.95,4) -> 465.40999 | E20: =C20+_xlfn.FORECAST.ETS.CONFINT(Data!B40,Data!$D$10:$D$36,Data!$B$10:$B$36,0.95,4) -> 731.78746 | F20: =Data!D36 -> 569 | G20: =ABS(C20-B20) -> 214.28716 | H20: =G20/B20 -> 0.5594965 | I20: =ABS(F20-B20) -> 186 | J20: =I20/B20 -> 0.48563969
A21: 2025 Q4 | B21: =Data!D41 -> 398 | C21: =_xlfn.FORECAST.ETS(Data!B41,Data!$D$10:$D$36,Data!$B$10:$B$36,4) -> 633.08126 | D21: =C21-_xlfn.FORECAST.ETS.CONFINT(Data!B41,Data!$D$10:$D$36,Data!$B$10:$B$36,0.95,4) -> 498.36552 | E21: =C21+_xlfn.FORECAST.ETS.CONFINT(Data!B41,Data!$D$10:$D$36,Data!$B$10:$B$36,0.95,4) -> 777.23555 | F21: =Data!D33 -> 589 | G21: =ABS(C21-B21) -> 235.08126 | H21: =G21/B21 -> 0.59065644 | I21: =ABS(F21-B21) -> 191 | J21: =I21/B21 -> 0.4798995
A22: 2026 Q1 | B22: =Data!D42 -> 352 | C22: =_xlfn.FORECAST.ETS(Data!B42,Data!$D$10:$D$36,Data!$B$10:$B$36,4) -> 634.9725 | D22: =C22-_xlfn.FORECAST.ETS.CONFINT(Data!B42,Data!$D$10:$D$36,Data!$B$10:$B$36,0.95,4) -> 476.89178 | E22: =C22+_xlfn.FORECAST.ETS.CONFINT(Data!B42,Data!$D$10:$D$36,Data!$B$10:$B$36,0.95,4) -> 786.62151 | F22: =Data!D34 -> 523 | G22: =ABS(C22-B22) -> 282.9725 | H22: =G22/B22 -> 0.80389914 | I22: =ABS(F22-B22) -> 171 | J22: =I22/B22 -> 0.48579545
A23: MAE / MAPE | C23: Inside 95%: | D23: =SUMPRODUCT((B17:B22>=D17:D22)*(B17:B22<=E17:E22))&" of 6" -> 0 of 6 | G23: =AVERAGE(G17:G22) -> 237.43685 | H23: =AVERAGE(H17:H22) -> 0.63248209 | I23: =AVERAGE(I17:I22) -> 188.5 | J23: =AVERAGE(J17:J22) -> 0.49809217
A27: Opioid hospitalizations
A28: Quarter | B28: Actual | C28: ETS forecast | D28: 95% low | E28: 95% high | F28: Seasonal naive | G28: ETS abs error | H28: ETS abs % error | I28: Naive abs error | J28: Naive abs % error
A29: 2024 Q4 | B29: =Data!E37 -> 415 | C29: =_xlfn.FORECAST.ETS(Data!B37,Data!$E$2:$E$36,Data!$B$2:$B$36,4) -> 534.85996 | D29: =C29-_xlfn.FORECAST.ETS.CONFINT(Data!B37,Data!$E$2:$E$36,Data!$B$2:$B$36,0.95,4) -> 463.07033 | E29: =C29+_xlfn.FORECAST.ETS.CONFINT(Data!B37,Data!$E$2:$E$36,Data!$B$2:$B$36,0.95,4) -> 609.37308 | F29: =Data!E33 -> 536 | G29: =ABS(C29-B29) -> 119.85996 | H29: =G29/B29 -> 0.28881918 | I29: =ABS(F29-B29) -> 121 | J29: =I29/B29 -> 0.29156627
A30: 2025 Q1 | B30: =Data!E38 -> 389 | C30: =_xlfn.FORECAST.ETS(Data!B38,Data!$E$2:$E$36,Data!$B$2:$B$36,4) -> 528.11915 | D30: =C30-_xlfn.FORECAST.ETS.CONFINT(Data!B38,Data!$E$2:$E$36,Data!$B$2:$B$36,0.95,4) -> 443.11364 | E30: =C30+_xlfn.FORECAST.ETS.CONFINT(Data!B38,Data!$E$2:$E$36,Data!$B$2:$B$36,0.95,4) -> 619.11899 | F30: =Data!E34 -> 559 | G30: =ABS(C30-B30) -> 139.11915 | H30: =G30/B30 -> 0.35763278 | I30: =ABS(F30-B30) -> 170 | J30: =I30/B30 -> 0.43701799
A31: 2025 Q2 | B31: =Data!E39 -> 409 | C31: =_xlfn.FORECAST.ETS(Data!B39,Data!$E$2:$E$36,Data!$B$2:$B$36,4) -> 563.98985 | D31: =C31-_xlfn.FORECAST.ETS.CONFINT(Data!B39,Data!$E$2:$E$36,Data!$B$2:$B$36,0.95,4) -> 465.92647 | E31: =C31+_xlfn.FORECAST.ETS.CONFINT(Data!B39,Data!$E$2:$E$36,Data!$B$2:$B$36,0.95,4) -> 661.70693 | F31: =Data!E35 -> 554 | G31: =ABS(C31-B31) -> 154.98985 | H31: =G31/B31 -> 0.37894828 | I31: =ABS(F31-B31) -> 145 | J31: =I31/B31 -> 0.35452323
A32: 2025 Q3 | B32: =Data!E40 -> 479 | C32: =_xlfn.FORECAST.ETS(Data!B40,Data!$E$2:$E$36,Data!$B$2:$B$36,4) -> 554.58173 | D32: =C32-_xlfn.FORECAST.ETS.CONFINT(Data!B40,Data!$E$2:$E$36,Data!$B$2:$B$36,0.95,4) -> 440.4164 | E32: =C32+_xlfn.FORECAST.ETS.CONFINT(Data!B40,Data!$E$2:$E$36,Data!$B$2:$B$36,0.95,4) -> 659.8928 | F32: =Data!E36 -> 540 | G32: =ABS(C32-B32) -> 75.581726 | H32: =G32/B32 -> 0.15779066 | I32: =ABS(F32-B32) -> 61 | J32: =I32/B32 -> 0.12734864
A33: 2025 Q4 | B33: =Data!E41 -> 439 | C33: =_xlfn.FORECAST.ETS(Data!B41,Data!$E$2:$E$36,Data!$B$2:$B$36,4) -> 546.89498 | D33: =C33-_xlfn.FORECAST.ETS.CONFINT(Data!B41,Data!$E$2:$E$36,Data!$B$2:$B$36,0.95,4) -> 418.68156 | E33: =C33+_xlfn.FORECAST.ETS.CONFINT(Data!B41,Data!$E$2:$E$36,Data!$B$2:$B$36,0.95,4) -> 679.41169 | F33: =Data!E33 -> 536 | G33: =ABS(C33-B33) -> 107.89498 | H33: =G33/B33 -> 0.24577444 | I33: =ABS(F33-B33) -> 97 | J33: =I33/B33 -> 0.22095672
A34: 2026 Q1 | B34: =Data!E42 -> 468 | C34: =_xlfn.FORECAST.ETS(Data!B42,Data!$E$2:$E$36,Data!$B$2:$B$36,4) -> 540.15417 | D34: =C34-_xlfn.FORECAST.ETS.CONFINT(Data!B42,Data!$E$2:$E$36,Data!$B$2:$B$36,0.95,4) -> 399.73421 | E34: =C34+_xlfn.FORECAST.ETS.CONFINT(Data!B42,Data!$E$2:$E$36,Data!$B$2:$B$36,0.95,4) -> 686.50483 | F34: =Data!E34 -> 559 | G34: =ABS(C34-B34) -> 72.154174 | H34: =G34/B34 -> 0.15417558 | I34: =ABS(F34-B34) -> 91 | J34: =I34/B34 -> 0.19444444
A35: MAE / MAPE | C35: Inside 95%: | D35: =SUMPRODUCT((B29:B34>=D29:D34)*(B29:B34<=E29:E34))&" of 6" -> 3 of 6 | G35: =AVERAGE(G29:G34) -> 111.59997 | H35: =AVERAGE(H29:H34) -> 0.26385682 | I35: =AVERAGE(I29:I34) -> 114.16667 | J35: =AVERAGE(J29:J34) -> 0.27097622
A39: Stimulant hospitalizations
A40: Quarter | B40: Actual | C40: ETS forecast | D40: 95% low | E40: 95% high | F40: Seasonal naive | G40: ETS abs error | H40: ETS abs % error | I40: Naive abs error | J40: Naive abs % error
A41: 2024 Q4 | B41: =Data!F37 -> 209 | C41: =_xlfn.FORECAST.ETS(Data!B37,Data!$F$2:$F$36,Data!$B$2:$B$36,4) -> 218.12585 | D41: =C41-_xlfn.FORECAST.ETS.CONFINT(Data!B37,Data!$F$2:$F$36,Data!$B$2:$B$36,0.95,4) -> 167.24137 | E41: =C41+_xlfn.FORECAST.ETS.CONFINT(Data!B37,Data!$F$2:$F$36,Data!$B$2:$B$36,0.95,4) -> 261.71627 | F41: =Data!F33 -> 233 | G41: =ABS(C41-B41) -> 9.1258542 | H41: =G41/B41 -> 0.043664374 | I41: =ABS(F41-B41) -> 24 | J41: =I41/B41 -> 0.11483254
A42: 2025 Q1 | B42: =Data!F38 -> 174 | C42: =_xlfn.FORECAST.ETS(Data!B38,Data!$F$2:$F$36,Data!$B$2:$B$36,4) -> 213.41702 | D42: =C42-_xlfn.FORECAST.ETS.CONFINT(Data!B38,Data!$F$2:$F$36,Data!$B$2:$B$36,0.95,4) -> 163.68803 | E42: =C42+_xlfn.FORECAST.ETS.CONFINT(Data!B38,Data!$F$2:$F$36,Data!$B$2:$B$36,0.95,4) -> 264.65046 | F42: =Data!F34 -> 229 | G42: =ABS(C42-B42) -> 39.417022 | H42: =G42/B42 -> 0.22653461 | I42: =ABS(F42-B42) -> 55 | J42: =I42/B42 -> 0.31609195
A43: 2025 Q2 | B43: =Data!F39 -> 184 | C43: =_xlfn.FORECAST.ETS(Data!B39,Data!$F$2:$F$36,Data!$B$2:$B$36,4) -> 260.86482 | D43: =C43-_xlfn.FORECAST.ETS.CONFINT(Data!B39,Data!$F$2:$F$36,Data!$B$2:$B$36,0.95,4) -> 204.68852 | E43: =C43+_xlfn.FORECAST.ETS.CONFINT(Data!B39,Data!$F$2:$F$36,Data!$B$2:$B$36,0.95,4) -> 316.6852 | F43: =Data!F35 -> 253 | G43: =ABS(C43-B43) -> 76.864822 | H43: =G43/B43 -> 0.4177436 | I43: =ABS(F43-B43) -> 69 | J43: =I43/B43 -> 0.375
A44: 2025 Q3 | B44: =Data!F40 -> 262 | C44: =_xlfn.FORECAST.ETS(Data!B40,Data!$F$2:$F$36,Data!$B$2:$B$36,4) -> 249.2816 | D44: =C44-_xlfn.FORECAST.ETS.CONFINT(Data!B40,Data!$F$2:$F$36,Data!$B$2:$B$36,0.95,4) -> 182.82913 | E44: =C44+_xlfn.FORECAST.ETS.CONFINT(Data!B40,Data!$F$2:$F$36,Data!$B$2:$B$36,0.95,4) -> 314.37047 | F44: =Data!F36 -> 251 | G44: =ABS(C44-B44) -> 12.718404 | H44: =G44/B44 -> 0.048543525 | I44: =ABS(F44-B44) -> 11 | J44: =I44/B44 -> 0.041984733
A45: 2025 Q4 | B45: =Data!F41 -> 193 | C45: =_xlfn.FORECAST.ETS(Data!B41,Data!$F$2:$F$36,Data!$B$2:$B$36,4) -> 216.74039 | D45: =C45-_xlfn.FORECAST.ETS.CONFINT(Data!B41,Data!$F$2:$F$36,Data!$B$2:$B$36,0.95,4) -> 141.92648 | E45: =C45+_xlfn.FORECAST.ETS.CONFINT(Data!B41,Data!$F$2:$F$36,Data!$B$2:$B$36,0.95,4) -> 293.53924 | F45: =Data!F33 -> 233 | G45: =ABS(C45-B45) -> 23.740389 | H45: =G45/B45 -> 0.1230072 | I45: =ABS(F45-B45) -> 40 | J45: =I45/B45 -> 0.20725389
A46: 2026 Q1 | B46: =Data!F42 -> 186 | C46: =_xlfn.FORECAST.ETS(Data!B42,Data!$F$2:$F$36,Data!$B$2:$B$36,4) -> 212.03156 | D46: =C46-_xlfn.FORECAST.ETS.CONFINT(Data!B42,Data!$F$2:$F$36,Data!$B$2:$B$36,0.95,4) -> 126.99609 | E46: =C46+_xlfn.FORECAST.ETS.CONFINT(Data!B42,Data!$F$2:$F$36,Data!$B$2:$B$36,0.95,4) -> 296.01301 | F46: =Data!F34 -> 229 | G46: =ABS(C46-B46) -> 26.031557 | H46: =G46/B46 -> 0.13995461 | I46: =ABS(F46-B46) -> 43 | J46: =I46/B46 -> 0.2311828
A47: MAE / MAPE | C47: Inside 95%: | D47: =SUMPRODUCT((B41:B46>=D41:D46)*(B41:B46<=E41:E46))&" of 6" -> 5 of 6 | G47: =AVERAGE(G41:G46) -> 31.316341 | H47: =AVERAGE(H41:H46) -> 0.16657465 | I47: =AVERAGE(I41:I46) -> 40.333333 | J47: =AVERAGE(J41:J46) -> 0.21439098

Sheet Forecast
A1: Forecast Q2 2026 to Q2 2027, fit on all quarters
A3: Opioid deaths
A4: Quarter | B4: Quarter start | C4: Forecast | D4: 80% low | E4: 80% high | F4: 95% low | G4: 95% high
A5: 2026 Q2 | B5: =DATE(2026,4,1) -> 46113 | C5: =_xlfn.FORECAST.ETS(B5,Data!$C$2:$C$42,Data!$B$2:$B$42,4) -> 435.46844 | D5: =C5-_xlfn.FORECAST.ETS.CONFINT(B5,Data!$C$2:$C$42,Data!$B$2:$B$42,0.8,4) -> 364.10229 | E5: =C5+_xlfn.FORECAST.ETS.CONFINT(B5,Data!$C$2:$C$42,Data!$B$2:$B$42,0.8,4) -> 506.32896 | F5: =C5-_xlfn.FORECAST.ETS.CONFINT(B5,Data!$C$2:$C$42,Data!$B$2:$B$42,0.95,4) -> 316.40414 | G5: =C5+_xlfn.FORECAST.ETS.CONFINT(B5,Data!$C$2:$C$42,Data!$B$2:$B$42,0.95,4) -> 552.95153
A6: 2026 Q3 | B6: =DATE(2026,7,1) -> 46204 | C6: =_xlfn.FORECAST.ETS(B6,Data!$C$2:$C$42,Data!$B$2:$B$42,4) -> 391.4911 | D6: =C6-_xlfn.FORECAST.ETS.CONFINT(B6,Data!$C$2:$C$42,Data!$B$2:$B$42,0.8,4) -> 288.81514 | E6: =C6+_xlfn.FORECAST.ETS.CONFINT(B6,Data!$C$2:$C$42,Data!$B$2:$B$42,0.8,4) -> 484.72765 | F6: =C6-_xlfn.FORECAST.ETS.CONFINT(B6,Data!$C$2:$C$42,Data!$B$2:$B$42,0.95,4) -> 244.50678 | G6: =C6+_xlfn.FORECAST.ETS.CONFINT(B6,Data!$C$2:$C$42,Data!$B$2:$B$42,0.95,4) -> 539.9012
A7: 2026 Q4 | B7: =DATE(2026,10,1) -> 46296 | C7: =_xlfn.FORECAST.ETS(B7,Data!$C$2:$C$42,Data!$B$2:$B$42,4) -> 403.09488 | D7: =C7-_xlfn.FORECAST.ETS.CONFINT(B7,Data!$C$2:$C$42,Data!$B$2:$B$42,0.8,4) -> 281.42044 | E7: =C7+_xlfn.FORECAST.ETS.CONFINT(B7,Data!$C$2:$C$42,Data!$B$2:$B$42,0.8,4) -> 524.1606 | F7: =C7-_xlfn.FORECAST.ETS.CONFINT(B7,Data!$C$2:$C$42,Data!$B$2:$B$42,0.95,4) -> 230.63444 | G7: =C7+_xlfn.FORECAST.ETS.CONFINT(B7,Data!$C$2:$C$42,Data!$B$2:$B$42,0.95,4) -> 589.91928
A8: 2027 Q1 | B8: =DATE(2027,1,1) -> 46388 | C8: =_xlfn.FORECAST.ETS(B8,Data!$C$2:$C$42,Data!$B$2:$B$42,4) -> 375.82317 | D8: =C8-_xlfn.FORECAST.ETS.CONFINT(B8,Data!$C$2:$C$42,Data!$B$2:$B$42,0.8,4) -> 237.24612 | E8: =C8+_xlfn.FORECAST.ETS.CONFINT(B8,Data!$C$2:$C$42,Data!$B$2:$B$42,0.8,4) -> 506.75329 | F8: =C8-_xlfn.FORECAST.ETS.CONFINT(B8,Data!$C$2:$C$42,Data!$B$2:$B$42,0.95,4) -> 162.17493 | G8: =C8+_xlfn.FORECAST.ETS.CONFINT(B8,Data!$C$2:$C$42,Data!$B$2:$B$42,0.95,4) -> 605.23715
A9: 2027 Q2 | B9: =DATE(2027,4,1) -> 46478 | C9: =_xlfn.FORECAST.ETS(B9,Data!$C$2:$C$42,Data!$B$2:$B$42,4) -> 422.59583 | D9: =C9-_xlfn.FORECAST.ETS.CONFINT(B9,Data!$C$2:$C$42,Data!$B$2:$B$42,0.8,4) -> 260.67987 | E9: =C9+_xlfn.FORECAST.ETS.CONFINT(B9,Data!$C$2:$C$42,Data!$B$2:$B$42,0.8,4) -> 592.36793 | F9: =C9-_xlfn.FORECAST.ETS.CONFINT(B9,Data!$C$2:$C$42,Data!$B$2:$B$42,0.95,4) -> 175.1729 | G9: =C9+_xlfn.FORECAST.ETS.CONFINT(B9,Data!$C$2:$C$42,Data!$B$2:$B$42,0.95,4) -> 677.38566
A12: Stimulant deaths
A13: Quarter | B13: Quarter start | C13: Forecast | D13: 80% low | E13: 80% high | F13: 95% low | G13: 95% high
A14: 2026 Q2 | B14: =DATE(2026,4,1) -> 46113 | C14: =_xlfn.FORECAST.ETS(B14,Data!$D$10:$D$42,Data!$B$10:$B$42,4) -> 409.07813 | D14: =C14-_xlfn.FORECAST.ETS.CONFINT(B14,Data!$D$10:$D$42,Data!$B$10:$B$42,0.8,4) -> 339.16184 | E14: =C14+_xlfn.FORECAST.ETS.CONFINT(B14,Data!$D$10:$D$42,Data!$B$10:$B$42,0.8,4) -> 477.27592 | F14: =C14-_xlfn.FORECAST.ETS.CONFINT(B14,Data!$D$10:$D$42,Data!$B$10:$B$42,0.95,4) -> 293.69958 | G14: =C14+_xlfn.FORECAST.ETS.CONFINT(B14,Data!$D$10:$D$42,Data!$B$10:$B$42,0.95,4) -> 515.50224
A15: 2026 Q3 | B15: =DATE(2026,7,1) -> 46204 | C15: =_xlfn.FORECAST.ETS(B15,Data!$D$10:$D$42,Data!$B$10:$B$42,4) -> 383.02446 | D15: =C15-_xlfn.FORECAST.ETS.CONFINT(B15,Data!$D$10:$D$42,Data!$B$10:$B$42,0.8,4) -> 303.66352 | E15: =C15+_xlfn.FORECAST.ETS.CONFINT(B15,Data!$D$10:$D$42,Data!$B$10:$B$42,0.8,4) -> 461.40441 | F15: =C15-_xlfn.FORECAST.ETS.CONFINT(B15,Data!$D$10:$D$42,Data!$B$10:$B$42,0.95,4) -> 256.61207 | G15: =C15+_xlfn.FORECAST.ETS.CONFINT(B15,Data!$D$10:$D$42,Data!$B$10:$B$42,0.95,4) -> 517.48269
A16: 2026 Q4 | B16: =DATE(2026,10,1) -> 46296 | C16: =_xlfn.FORECAST.ETS(B16,Data!$D$10:$D$42,Data!$B$10:$B$42,4) -> 381.57456 | D16: =C16-_xlfn.FORECAST.ETS.CONFINT(B16,Data!$D$10:$D$42,Data!$B$10:$B$42,0.8,4) -> 290.69754 | E16: =C16+_xlfn.FORECAST.ETS.CONFINT(B16,Data!$D$10:$D$42,Data!$B$10:$B$42,0.8,4) -> 475.39633 | F16: =C16-_xlfn.FORECAST.ETS.CONFINT(B16,Data!$D$10:$D$42,Data!$B$10:$B$42,0.95,4) -> 232.99617 | G16: =C16+_xlfn.FORECAST.ETS.CONFINT(B16,Data!$D$10:$D$42,Data!$B$10:$B$42,0.95,4) -> 529.80527
A17: 2027 Q1 | B17: =DATE(2027,1,1) -> 46388 | C17: =_xlfn.FORECAST.ETS(B17,Data!$D$10:$D$42,Data!$B$10:$B$42,4) -> 390.97222 | D17: =C17-_xlfn.FORECAST.ETS.CONFINT(B17,Data!$D$10:$D$42,Data!$B$10:$B$42,0.8,4) -> 290.60185 | E17: =C17+_xlfn.FORECAST.ETS.CONFINT(B17,Data!$D$10:$D$42,Data!$B$10:$B$42,0.8,4) -> 492.75942 | F17: =C17-_xlfn.FORECAST.ETS.CONFINT(B17,Data!$D$10:$D$42,Data!$B$10:$B$42,0.95,4) -> 231.81104 | G17: =C17+_xlfn.FORECAST.ETS.CONFINT(B17,Data!$D$10:$D$42,Data!$B$10:$B$42,0.95,4) -> 553.63306
A18: 2027 Q2 | B18: =DATE(2027,4,1) -> 46478 | C18: =_xlfn.FORECAST.ETS(B18,Data!$D$10:$D$42,Data!$B$10:$B$42,4) -> 434.57813 | D18: =C18-_xlfn.FORECAST.ETS.CONFINT(B18,Data!$D$10:$D$42,Data!$B$10:$B$42,0.8,4) -> 320.5354 | E18: =C18+_xlfn.FORECAST.ETS.CONFINT(B18,Data!$D$10:$D$42,Data!$B$10:$B$42,0.8,4) -> 552.22875 | F18: =C18-_xlfn.FORECAST.ETS.CONFINT(B18,Data!$D$10:$D$42,Data!$B$10:$B$42,0.95,4) -> 231.93709 | G18: =C18+_xlfn.FORECAST.ETS.CONFINT(B18,Data!$D$10:$D$42,Data!$B$10:$B$42,0.95,4) -> 621.02406
A21: Opioid hospitalizations
A22: Quarter | B22: Quarter start | C22: Forecast | D22: 80% low | E22: 80% high | F22: 95% low | G22: 95% high
A23: 2026 Q2 | B23: =DATE(2026,4,1) -> 46113 | C23: =_xlfn.FORECAST.ETS(B23,Data!$E$2:$E$42,Data!$B$2:$B$42,4) -> 494.73693 | D23: =C23-_xlfn.FORECAST.ETS.CONFINT(B23,Data!$E$2:$E$42,Data!$B$2:$B$42,0.8,4) -> 447.10593 | E23: =C23+_xlfn.FORECAST.ETS.CONFINT(B23,Data!$E$2:$E$42,Data!$B$2:$B$42,0.8,4) -> 544.19642 | F23: =C23-_xlfn.FORECAST.ETS.CONFINT(B23,Data!$E$2:$E$42,Data!$B$2:$B$42,0.95,4) -> 414.3082 | G23: =C23+_xlfn.FORECAST.ETS.CONFINT(B23,Data!$E$2:$E$42,Data!$B$2:$B$42,0.95,4) -> 577.91579
A24: 2026 Q3 | B24: =DATE(2026,7,1) -> 46204 | C24: =_xlfn.FORECAST.ETS(B24,Data!$E$2:$E$42,Data!$B$2:$B$42,4) -> 506.0764 | D24: =C24-_xlfn.FORECAST.ETS.CONFINT(B24,Data!$E$2:$E$42,Data!$B$2:$B$42,0.8,4) -> 450.56799 | E24: =C24+_xlfn.FORECAST.ETS.CONFINT(B24,Data!$E$2:$E$42,Data!$B$2:$B$42,0.8,4) -> 562.87783 | F24: =C24-_xlfn.FORECAST.ETS.CONFINT(B24,Data!$E$2:$E$42,Data!$B$2:$B$42,0.95,4) -> 411.22777 | G24: =C24+_xlfn.FORECAST.ETS.CONFINT(B24,Data!$E$2:$E$42,Data!$B$2:$B$42,0.95,4) -> 598.54399
A25: 2026 Q4 | B25: =DATE(2026,10,1) -> 46296 | C25: =_xlfn.FORECAST.ETS(B25,Data!$E$2:$E$42,Data!$B$2:$B$42,4) -> 459.54516 | D25: =C25-_xlfn.FORECAST.ETS.CONFINT(B25,Data!$E$2:$E$42,Data!$B$2:$B$42,0.8,4) -> 390.96906 | E25: =C25+_xlfn.FORECAST.ETS.CONFINT(B25,Data!$E$2:$E$42,Data!$B$2:$B$42,0.8,4) -> 528.39866 | F25: =C25-_xlfn.FORECAST.ETS.CONFINT(B25,Data!$E$2:$E$42,Data!$B$2:$B$42,0.95,4) -> 357.05264 | G25: =C25+_xlfn.FORECAST.ETS.CONFINT(B25,Data!$E$2:$E$42,Data!$B$2:$B$42,0.95,4) -> 557.08811
A26: 2027 Q1 | B26: =DATE(2027,1,1) -> 46388 | C26: =_xlfn.FORECAST.ETS(B26,Data!$E$2:$E$42,Data!$B$2:$B$42,4) -> 462.98946 | D26: =C26-_xlfn.FORECAST.ETS.CONFINT(B26,Data!$E$2:$E$42,Data!$B$2:$B$42,0.8,4) -> 390.6701 | E26: =C26+_xlfn.FORECAST.ETS.CONFINT(B26,Data!$E$2:$E$42,Data!$B$2:$B$42,0.8,4) -> 536.80349 | F26: =C26-_xlfn.FORECAST.ETS.CONFINT(B26,Data!$E$2:$E$42,Data!$B$2:$B$42,0.95,4) -> 343.37812 | G26: =C26+_xlfn.FORECAST.ETS.CONFINT(B26,Data!$E$2:$E$42,Data!$B$2:$B$42,0.95,4) -> 580.51152
A27: 2027 Q2 | B27: =DATE(2027,4,1) -> 46478 | C27: =_xlfn.FORECAST.ETS(B27,Data!$E$2:$E$42,Data!$B$2:$B$42,4) -> 496.64811 | D27: =C27-_xlfn.FORECAST.ETS.CONFINT(B27,Data!$E$2:$E$42,Data!$B$2:$B$42,0.8,4) -> 402.5296 | E27: =C27+_xlfn.FORECAST.ETS.CONFINT(B27,Data!$E$2:$E$42,Data!$B$2:$B$42,0.8,4) -> 585.47371 | F27: =C27-_xlfn.FORECAST.ETS.CONFINT(B27,Data!$E$2:$E$42,Data!$B$2:$B$42,0.95,4) -> 350.06359 | G27: =C27+_xlfn.FORECAST.ETS.CONFINT(B27,Data!$E$2:$E$42,Data!$B$2:$B$42,0.95,4) -> 633.70503
A30: Stimulant hospitalizations
A31: Quarter | B31: Quarter start | C31: Forecast | D31: 80% low | E31: 80% high | F31: 95% low | G31: 95% high
A32: 2026 Q2 | B32: =DATE(2026,4,1) -> 46113 | C32: =_xlfn.FORECAST.ETS(B32,Data!$F$2:$F$42,Data!$B$2:$B$42,4) -> 220.82209 | D32: =C32-_xlfn.FORECAST.ETS.CONFINT(B32,Data!$F$2:$F$42,Data!$B$2:$B$42,0.8,4) -> 193.73128 | E32: =C32+_xlfn.FORECAST.ETS.CONFINT(B32,Data!$F$2:$F$42,Data!$B$2:$B$42,0.8,4) -> 249.28631 | F32: =C32-_xlfn.FORECAST.ETS.CONFINT(B32,Data!$F$2:$F$42,Data!$B$2:$B$42,0.95,4) -> 172.96306 | G32: =C32+_xlfn.FORECAST.ETS.CONFINT(B32,Data!$F$2:$F$42,Data!$B$2:$B$42,0.95,4) -> 271.14163
A33: 2026 Q3 | B33: =DATE(2026,7,1) -> 46204 | C33: =_xlfn.FORECAST.ETS(B33,Data!$F$2:$F$42,Data!$B$2:$B$42,4) -> 234.73585 | D33: =C33-_xlfn.FORECAST.ETS.CONFINT(B33,Data!$F$2:$F$42,Data!$B$2:$B$42,0.8,4) -> 203.64814 | E33: =C33+_xlfn.FORECAST.ETS.CONFINT(B33,Data!$F$2:$F$42,Data!$B$2:$B$42,0.8,4) -> 268.75241 | F33: =C33-_xlfn.FORECAST.ETS.CONFINT(B33,Data!$F$2:$F$42,Data!$B$2:$B$42,0.95,4) -> 179.72245 | G33: =C33+_xlfn.FORECAST.ETS.CONFINT(B33,Data!$F$2:$F$42,Data!$B$2:$B$42,0.95,4) -> 287.76214
A34: 2026 Q4 | B34: =DATE(2026,10,1) -> 46296 | C34: =_xlfn.FORECAST.ETS(B34,Data!$F$2:$F$42,Data!$B$2:$B$42,4) -> 187.54663 | D34: =C34-_xlfn.FORECAST.ETS.CONFINT(B34,Data!$F$2:$F$42,Data!$B$2:$B$42,0.8,4) -> 149.3703 | E34: =C34+_xlfn.FORECAST.ETS.CONFINT(B34,Data!$F$2:$F$42,Data!$B$2:$B$42,0.8,4) -> 223.94164 | F34: =C34-_xlfn.FORECAST.ETS.CONFINT(B34,Data!$F$2:$F$42,Data!$B$2:$B$42,0.95,4) -> 124.76075 | G34: =C34+_xlfn.FORECAST.ETS.CONFINT(B34,Data!$F$2:$F$42,Data!$B$2:$B$42,0.95,4) -> 245.72181
A35: 2027 Q1 | B35: =DATE(2027,1,1) -> 46388 | C35: =_xlfn.FORECAST.ETS(B35,Data!$F$2:$F$42,Data!$B$2:$B$42,4) -> 179.68303 | D35: =C35-_xlfn.FORECAST.ETS.CONFINT(B35,Data!$F$2:$F$42,Data!$B$2:$B$42,0.8,4) -> 138.44715 | E35: =C35+_xlfn.FORECAST.ETS.CONFINT(B35,Data!$F$2:$F$42,Data!$B$2:$B$42,0.8,4) -> 220.74954 | F35: =C35-_xlfn.FORECAST.ETS.CONFINT(B35,Data!$F$2:$F$42,Data!$B$2:$B$42,0.95,4) -> 111.31126 | G35: =C35+_xlfn.FORECAST.ETS.CONFINT(B35,Data!$F$2:$F$42,Data!$B$2:$B$42,0.95,4) -> 249.8273
A36: 2027 Q2 | B36: =DATE(2027,4,1) -> 46478 | C36: =_xlfn.FORECAST.ETS(B36,Data!$F$2:$F$42,Data!$B$2:$B$42,4) -> 214.13413 | D36: =C36-_xlfn.FORECAST.ETS.CONFINT(B36,Data!$F$2:$F$42,Data!$B$2:$B$42,0.8,4) -> 162.89115 | E36: =C36+_xlfn.FORECAST.ETS.CONFINT(B36,Data!$F$2:$F$42,Data!$B$2:$B$42,0.8,4) -> 266.32719 | F36: =C36-_xlfn.FORECAST.ETS.CONFINT(B36,Data!$F$2:$F$42,Data!$B$2:$B$42,0.95,4) -> 132.12497 | G36: =C36+_xlfn.FORECAST.ETS.CONFINT(B36,Data!$F$2:$F$42,Data!$B$2:$B$42,0.95,4) -> 299.81968
